<robot name="my_robot" xmlns:xacro="http://ros.org/wiki/xacro">

  <!-- Tất cả các liên kết và khớp nối được khai báo ở đây -->

  <material name="white">
    <color rgba=" 1 1 1 1 " />
  </material>

  <material name="orange">
    <color rgba=" 1 0.3 0.1 1 " />
  </material>

  <material name="blue">
    <color rgba=" 0.2 0.2 1 1 " />
  </material>

  <material name="black">
    <color rgba=" 0 0 0 1 " />
  </material>

  <link name="base_link">
  </link>


  <joint name="chassis_joint" type="fixed">
    <parent link="base_link" />
    <child link="chassis" />
    <origin xyz="-0.5 0 0" />
  </joint>


  <link name="chassis">
    <visual>
      <origin xyz="0.3 0 0.075"></origin>
      <geometry>
        <box size="0.6 0.4 0.15" />
      </geometry>
      <material name="white" />
    </visual>
  </link>


  <!-- LEFT WHEEL LINK -->

  <joint name="left_wheel_joint" type="continuous">
    <parent link="base_link" />
    <child link="left_wheel" />
    <origin xyz="0 -0.2 0" rpy="-1.5708 0 0" />
    <axis xyz="0 0 1" />
  </joint>

  <link name="left_wheel">
    <visual>
      <geometry>
        <cylinder radius="0.05" length="0.04" />
      </geometry>
      <material name="blue" />
    </visual>
  </link>

  <!-- RIGHT WHEEL LINK -->

  <joint name="right_wheel_joint" type="continuous">
    <parent link="base_link" />
    <child link="right_wheel" />
    <origin xyz="0 0.2 0" rpy="1.5708 0 0" />
    <axis xyz="0 0 -1" />
  </joint>

  <link name="right_wheel">
    <visual>
      <geometry>
        <cylinder radius="0.05" length="0.04" />
      </geometry>
      <material name="blue" />
    </visual>
  </link>


  <!-- RIGHT CASTER WHEEL LINK -->

  <joint name="right_caster_wheel_joint" type="fixed">
    <parent link="chassis" />
    <child link="right_caster_wheel" />
    <origin xyz="0.05 0.175 0"/>
  </joint>

  <link name="right_caster_wheel">
    <visual>
      <geometry>
        <sphere  radius="0.05"/>
      </geometry>
      <material name="black" />
    </visual>
  </link>

  <!-- LEFT CASTER WHEEL LINK -->

  <joint name="left_caster_wheel_joint" type="fixed">
    <parent link="chassis" />
    <child link="left_caster_wheel" />
    <origin xyz="0.05 -0.175 0"/>
  </joint>

  <link name="left_caster_wheel">
    <visual>
      <geometry>
        <sphere radius="0.05"/>
      </geometry>
      <material name="black" />
    </visual>
  </link>

</robot>